<?xml version="1.0"?>

<robot xmlns:xacro="http://www.ros.org/wiki/xacro">

    <!-- some constants -->
    <xacro:property name="PI" value="3.1415926535897931" />
    <xacro:property name="joint_damping" value="10.0" />
    <xacro:property name="joint_friction" value="0.1" />
    <xacro:property name="A1_position_limit" value="170" />
    <xacro:property name="A2_position_limit" value="120" />
    <xacro:property name="A3_position_limit" value="170" />
    <xacro:property name="A4_position_limit" value="120" />
    <xacro:property name="A5_position_limit" value="170" />
    <xacro:property name="A6_position_limit" value="120" />
    <xacro:property name="A7_position_limit" value="175" />
    <xacro:property name="A1_velocity_limit" value="85" />
    <xacro:property name="A2_velocity_limit" value="85" />
    <xacro:property name="A3_velocity_limit" value="100" />
    <xacro:property name="A4_velocity_limit" value="75" />
    <xacro:property name="A5_velocity_limit" value="130" />
    <xacro:property name="A6_velocity_limit" value="135" />
    <xacro:property name="A7_velocity_limit" value="135" />
    <xacro:property name="effort_limit" value="200" />

    <!-- includes -->
    <xacro:include filename="$(find lbr_description)/gazebo/lbr.gazebo.xacro" />
    <xacro:include filename="$(find lbr_ros2_control)/config/lbr_system_interface.xacro" />

    <!-- robot as extracted via https://github.com/syuntoku14/fusion2urdf -->
    <xacro:macro name="iiwa14"
        params="robot_name:=^|lbr port_id:=^|30200 sim:=^|true">

        <link name="link_0">
            <inertial>
                <origin xyz="-0.1 0 0.07" rpy="0 0 0" />
                <mass value="5" />
                <inertia ixx="0.05" ixy="0" ixz="0" iyy="0.06" iyz="0" izz="0.03" />
            </inertial>
            <visual>
                <origin xyz="0 0 0" rpy="0 0 0" />
                <geometry>
                    <mesh filename="package://lbr_description/meshes/iiwa14/visual/link_0.stl" />
                </geometry>
            </visual>
            <collision>
                <origin xyz="0 0 0" rpy="0 0 0" />
                <geometry>
                    <mesh filename="package://lbr_description/meshes/iiwa14/collision/link_0.stl" />
                </geometry>
            </collision>
        </link>

        <joint name="A1" type="revolute">
            <origin xyz="0 0 0.1575" rpy="0 0 0" />
            <parent link="link_0" />
            <child link="link_1" />
            <axis xyz="0 0 1" />
            <limit effort="${effort_limit}" lower="${-A1_position_limit * PI / 180}"
                upper="${A1_position_limit * PI / 180}"
                velocity="${A1_velocity_limit * PI / 180}" />
            <dynamics damping="${joint_damping}" friction="${joint_friction}" />
        </joint>

        <link name="link_1">
            <inertial>
                <origin xyz="0 -0.03 0.12" rpy="0 0 0" />
                <mass value="5.76" />
                <inertia ixx="0.0333" ixy="0" ixz="0" iyy="0.033" iyz="0" izz="0.0123" />
            </inertial>
            <visual>
                <origin xyz="0 0 0" rpy="0 0 0" />
                <geometry>
                    <mesh filename="package://lbr_description/meshes/iiwa14/visual/link_1.stl" />
                </geometry>
            </visual>
            <collision>
                <origin xyz="0 0 0" rpy="0 0 0" />
                <geometry>
                    <mesh filename="package://lbr_description/meshes/iiwa14/collision/link_1.stl" />
                </geometry>
            </collision>
        </link>

        <joint name="A2" type="revolute">
            <origin xyz="0 0 0.2025" rpy="${PI / 2}   0 ${PI}" />
            <parent link="link_1" />
            <child link="link_2" />
            <axis xyz="0 0 1" />
            <limit effort="${effort_limit}" lower="${-A2_position_limit * PI / 180}"
                upper="${A2_position_limit * PI / 180}"
                velocity="${A2_velocity_limit * PI / 180}" />
            <dynamics damping="${joint_damping}" friction="${joint_friction}" />
        </joint>

        <link name="link_2">
            <inertial>
                <origin xyz="0.0003 0.059 0.042" rpy="0 0 0" />
                <mass value="4" />
                <inertia ixx="0.05" ixy="0" ixz="0" iyy="0.018" iyz="0" izz="0.044" />
            </inertial>
            <visual>
                <origin xyz="0 0 0" rpy="0 0 0" />
                <geometry>
                    <mesh filename="package://lbr_description/meshes/iiwa14/visual/link_2.stl" />
                </geometry>
            </visual>
            <collision>
                <origin xyz="0 0 0" rpy="0 0 0" />
                <geometry>
                    <mesh filename="package://lbr_description/meshes/iiwa14/collision/link_2.stl" />
                </geometry>
            </collision>
        </link>

        <joint name="A3" type="revolute">
            <origin xyz="0 0.2045 0" rpy="${PI / 2} 0 ${PI}" />
            <parent link="link_2" />
            <child link="link_3" />
            <axis xyz="0 0 1" />
            <limit effort="${effort_limit}" lower="${-A3_position_limit * PI / 180}"
                upper="${A3_position_limit * PI / 180}"
                velocity="${A3_velocity_limit * PI / 180}" />
            <dynamics damping="${joint_damping}" friction="${joint_friction}" />
        </joint>

        <link name="link_3">
            <inertial>
                <origin xyz="0 0.03 0.13" rpy="0 0 0" />
                <mass value="3" />
                <inertia ixx="0.08" ixy="0" ixz="0" iyy="0.075" iyz="0" izz="0.01" />
            </inertial>
            <visual>
                <origin xyz="0 0 0" rpy="0 0 0" />
                <geometry>
                    <mesh filename="package://lbr_description/meshes/iiwa14/visual/link_3.stl" />
                </geometry>
            </visual>
            <collision>
                <origin xyz="0 0 0" rpy="0 0 0" />
                <geometry>
                    <mesh filename="package://lbr_description/meshes/iiwa14/collision/link_3.stl" />
                </geometry>
            </collision>
        </link>

        <joint name="A4" type="revolute">
            <origin xyz="0 0 0.2155" rpy="${PI / 2} 0 0" />
            <parent link="link_3" />
            <child link="link_4" />
            <axis xyz="0 0 1" />
            <limit effort="${effort_limit}" lower="${-A4_position_limit * PI / 180}"
                upper="${A4_position_limit * PI / 180}"
                velocity="${A4_velocity_limit * PI / 180}" />
            <dynamics damping="${joint_damping}" friction="${joint_friction}" />
        </joint>

        <link name="link_4">
            <inertial>
                <origin xyz="0 0.067 0.034" rpy="0 0 0" />
                <mass value="2.7" />
                <inertia ixx="0.03" ixy="0" ixz="0" iyy="0.01" iyz="0" izz="0.029" />
            </inertial>
            <visual>
                <origin xyz="0 0 0" rpy="0 0 0" />
                <geometry>
                    <mesh filename="package://lbr_description/meshes/iiwa14/visual/link_4.stl" />
                </geometry>
            </visual>
            <collision>
                <origin xyz="0 0 0" rpy="0 0 0" />
                <geometry>
                    <mesh filename="package://lbr_description/meshes/iiwa14/collision/link_4.stl" />
                </geometry>
            </collision>
        </link>

        <joint name="A5" type="revolute">
            <origin xyz="0 0.1845 0" rpy="${-PI / 2} ${PI} 0" />
            <parent link="link_4" />
            <child link="link_5" />
            <axis xyz="0 0 1" />
            <limit effort="${effort_limit}" lower="${-A5_position_limit * PI / 180}"
                upper="${A5_position_limit * PI / 180}"
                velocity="${A5_velocity_limit * PI / 180}" />
            <dynamics damping="${joint_damping}" friction="${joint_friction}" />
        </joint>

        <link name="link_5">
            <inertial>
                <origin xyz="0.0001 0.021 0.076" rpy="0 0 0" />
                <mass value="1.7" />
                <inertia ixx="0.02" ixy="0" ixz="0" iyy="0.018" iyz="0" izz="0.005" />
            </inertial>
            <visual>
                <origin xyz="0 0 0" rpy="0 0 0" />
                <geometry>
                    <mesh filename="package://lbr_description/meshes/iiwa14/visual/link_5.stl" />
                </geometry>
            </visual>
            <collision>
                <origin xyz="0 0 0" rpy="0 0 0" />
                <geometry>
                    <mesh filename="package://lbr_description/meshes/iiwa14/collision/link_5.stl" />
                </geometry>
            </collision>
        </link>

        <joint name="A6" type="revolute">
            <origin xyz="0 0 0.2155" rpy="${PI / 2} 0 0" />
            <parent link="link_5" />
            <child link="link_6" />
            <axis xyz="0 0 1" />
            <limit effort="${effort_limit}" lower="${-A6_position_limit * PI / 180}"
                upper="${A6_position_limit * PI / 180}"
                velocity="${A6_velocity_limit * PI / 180}" />
            <dynamics damping="${joint_damping}" friction="${joint_friction}" />
        </joint>

        <link name="link_6">
            <inertial>
                <origin xyz="0 0.0006 0.0004" rpy="0 0 0" />
                <mass value="1.8" />
                <inertia ixx="0.005" ixy="0" ixz="0" iyy="0.0036" iyz="0" izz="0.0047" />
            </inertial>
            <visual>
                <origin xyz="0 0 0" rpy="0 0 0" />
                <geometry>
                    <mesh filename="package://lbr_description/meshes/iiwa14/visual/link_6.stl" />
                </geometry>
            </visual>
            <collision>
                <origin xyz="0 0 0" rpy="0 0 0" />
                <geometry>
                    <mesh filename="package://lbr_description/meshes/iiwa14/collision/link_6.stl" />
                </geometry>
            </collision>
        </link>

        <joint name="A7" type="revolute">
            <origin xyz="0 0.081 0" rpy="${- PI / 2} ${PI} 0" />
            <parent link="link_6" />
            <child link="link_7" />
            <axis xyz="0 0 1" />
            <limit effort="${effort_limit}" lower="${-A7_position_limit * PI / 180}"
                upper="${A7_position_limit * PI / 180}"
                velocity="${A7_velocity_limit * PI / 180}" />
            <dynamics damping="${joint_damping}" friction="${joint_friction}" />
        </joint>

        <link name="link_7">
            <inertial>
                <origin xyz="0 0 0.02" rpy="0 0 0" />
                <mass value="0.3" />
                <inertia ixx="0.001" ixy="0" ixz="0" iyy="0.001" iyz="0" izz="0.001" />
            </inertial>
            <visual>
                <origin xyz="0 0 0" rpy="0 0 0" />
                <geometry>
                    <mesh filename="package://lbr_description/meshes/iiwa14/visual/link_7.stl" />
                </geometry>
            </visual>
            <collision>
                <origin xyz="0 0 0" rpy="0 0 0" />
                <geometry>
                    <mesh filename="package://lbr_description/meshes/iiwa14/collision/link_7.stl" />
                </geometry>
            </collision>
        </link>

        <joint name="joint_ee" type="fixed">
            <parent link="link_7" />
            <child link="link_ee" />
            <origin xyz="0 0 0.045" rpy="0 0 0" />
        </joint>

        <link name="link_ee">
        </link>

        <xacro:lbr_gazebo robot_name="${robot_name}" />
        <!-- TODO: move modes to args, decouple urdf/gazebo/controls -->
        <xacro:lbr_system_interface
            A1_position_limit="${A1_position_limit * PI / 180}"
            A2_position_limit="${A2_position_limit * PI / 180}"
            A3_position_limit="${A3_position_limit * PI / 180}"
            A4_position_limit="${A4_position_limit * PI / 180}"
            A5_position_limit="${A5_position_limit * PI / 180}"
            A6_position_limit="${A6_position_limit * PI / 180}"
            A7_position_limit="${A7_position_limit * PI / 180}"
            A1_velocity_limit="${A1_velocity_limit * PI / 180}"
            A2_velocity_limit="${A2_velocity_limit * PI / 180}"
            A3_velocity_limit="${A3_velocity_limit * PI / 180}"
            A4_velocity_limit="${A4_velocity_limit * PI / 180}"
            A5_velocity_limit="${A5_velocity_limit * PI / 180}"
            A6_velocity_limit="${A6_velocity_limit * PI / 180}"
            A7_velocity_limit="${A7_velocity_limit * PI / 180}"
            max_torque="${effort_limit}"
            sim="${sim}" remote_host="INADDR_ANY" port_id="${port_id}" />

    </xacro:macro>
</robot>